<mujoco model="{YOUR_NAME}">
  <compiler angle="radian" meshdir="assets"/>

  <option timestep="0.001" iterations="50" tolerance="1e-9" solver="Newton" jacobian="dense" cone="pyramidal"/>

  <default>
    <default class="panda">
      <material specular="0.5" shininess="0.25"/>
      <joint armature="0.1" damping="1" axis="0 0 1" limited="true" range="-2.8973 2.8973"/>
      <general ctrllimited="true" forcelimited="true" dyntype="none" biastype="affine"
          ctrlrange="-2.8973 2.8973" forcerange="-87 87"/>
      <default class="finger">
        <joint axis="0 1 0" type="slide" range="0 0.04"/>
      </default>

      <default class="visual">
        <geom type="mesh" contype="0" conaffinity="0" group="2"/>
      </default>
      <default class="collision">
        <geom type="mesh" group="3"/>
        <default class="fingertip_pad_collision_1">
          <geom type="box" size="0.0085 0.004 0.0085" pos="0 0.0055 0.0445"/>
        </default>
        <default class="fingertip_pad_collision_2">
          <geom type="box" size="0.003 0.002 0.003" pos="0.0055 0.002 0.05"/>
        </default>
        <default class="fingertip_pad_collision_3">
          <geom type="box" size="0.003 0.002 0.003" pos="-0.0055 0.002 0.05"/>
        </default>
        <default class="fingertip_pad_collision_4">
          <geom type="box" size="0.003 0.002 0.0035" pos="0.0055 0.002 0.0395"/>
        </default>
        <default class="fingertip_pad_collision_5">
          <geom type="box" size="0.003 0.002 0.0035" pos="-0.0055 0.002 0.0395"/>
        </default>
      </default>
    </default>
  </default>

  <asset>
    <material class="panda" name="white" rgba="1 1 1 1"/>
    <material class="panda" name="off_white" rgba="0.901961 0.921569 0.929412 1"/>
    <material class="panda" name="black" rgba="0.25 0.25 0.25 1"/>
    <material class="panda" name="green" rgba="0 1 0 1"/>
    <material class="panda" name="light_blue" rgba="0.039216 0.541176 0.780392 1"/>

    <!-- Collision meshes -->
    <mesh name="link0_c" file="link0.stl"/>
    <mesh name="link1_c" file="link1.stl"/>
    <mesh name="link2_c" file="link2.stl"/>
    <mesh name="link3_c" file="link3.stl"/>
    <mesh name="link4_c" file="link4.stl"/>
    <mesh name="link5_c0" file="link5_collision_0.obj"/>
    <mesh name="link5_c1" file="link5_collision_1.obj"/>
    <mesh name="link5_c2" file="link5_collision_2.obj"/>
    <mesh name="link6_c" file="link6.stl"/>
    <mesh name="link7_c" file="link7.stl"/>
    <mesh name="hand_c" file="hand.stl"/>

    <!-- Visual meshes -->
    <mesh file="link0_0.obj"/>
    <mesh file="link0_1.obj"/>
    <mesh file="link0_2.obj"/>
    <mesh file="link0_3.obj"/>
    <mesh file="link0_4.obj"/>
    <mesh file="link0_5.obj"/>
    <mesh file="link0_7.obj"/>
    <mesh file="link0_8.obj"/>
    <mesh file="link0_9.obj"/>
    <mesh file="link0_10.obj"/>
    <mesh file="link0_11.obj"/>
    <mesh file="link1.obj"/>
    <mesh file="link2.obj"/>
    <mesh file="link3_0.obj"/>
    <mesh file="link3_1.obj"/>
    <mesh file="link3_2.obj"/>
    <mesh file="link3_3.obj"/>
    <mesh file="link4_0.obj"/>
    <mesh file="link4_1.obj"/>
    <mesh file="link4_2.obj"/>
    <mesh file="link4_3.obj"/>
    <mesh file="link5_0.obj"/>
    <mesh file="link5_1.obj"/>
    <mesh file="link5_2.obj"/>
    <mesh file="link6_0.obj"/>
    <mesh file="link6_1.obj"/>
    <mesh file="link6_2.obj"/>
    <mesh file="link6_3.obj"/>
    <mesh file="link6_4.obj"/>
    <mesh file="link6_5.obj"/>
    <mesh file="link6_6.obj"/>
    <mesh file="link6_7.obj"/>
    <mesh file="link6_8.obj"/>
    <mesh file="link6_9.obj"/>
    <mesh file="link6_10.obj"/>
    <mesh file="link6_11.obj"/>
    <mesh file="link6_12.obj"/>
    <mesh file="link6_13.obj"/>
    <mesh file="link6_14.obj"/>
    <mesh file="link6_15.obj"/>
    <mesh file="link6_16.obj"/>
    <mesh file="link7_0.obj"/>
    <mesh file="link7_1.obj"/>
    <mesh file="link7_2.obj"/>
    <mesh file="link7_3.obj"/>
    <mesh file="link7_4.obj"/>
    <mesh file="link7_5.obj"/>
    <mesh file="link7_6.obj"/>
    <mesh file="link7_7.obj"/>
    <mesh file="hand_0.obj"/>
    <mesh file="hand_1.obj"/>
    <mesh file="hand_2.obj"/>
    <mesh file="hand_3.obj"/>
    <mesh file="hand_4.obj"/>
    <mesh file="finger_0.obj"/>
    <mesh file="finger_1.obj"/>
  </asset>

  <worldbody>
    <light name="top" pos="0 0 2" mode="trackcom"/>
    <body name="{YOUR_NAME}_link0" childclass="panda" pos="0 0 0" quat="0 0 0 1" gravcomp="1">
      <inertial mass="0.629769" pos="-0.041018 -0.00014 0.049974"
          fullinertia="0.00315 0.00388 0.004285 8.2904e-7 0.00015 8.2299e-6"/>
      <geom mesh="link0_0" material="off_white" class="visual"/>
      <geom mesh="link0_1" material="black" class="visual"/>
      <geom mesh="link0_2" material="off_white" class="visual"/>
      <geom mesh="link0_3" material="black" class="visual"/>
      <geom mesh="link0_4" material="off_white" class="visual"/>
      <geom mesh="link0_5" material="black" class="visual"/>
      <geom mesh="link0_7" material="white" class="visual"/>
      <geom mesh="link0_8" material="white" class="visual"/>
      <geom mesh="link0_9" material="black" class="visual"/>
      <geom mesh="link0_10" material="off_white" class="visual"/>
      <geom mesh="link0_11" material="white" class="visual"/>
      <geom mesh="link0_c" class="collision"/>
      <body name="{YOUR_NAME}_link1" pos="0 0 0.333" gravcomp="1">
        <site name="{YOUR_NAME}_joint1_site" pos="0 0.0 0.0" size=".01 .01 .01" type="ellipsoid" rgba=".8 .2 .1 0"/>
        <inertial mass="4.970684" pos="0.003875 0.002081 -0.04762"
            fullinertia="0.70337 0.70661 0.0091170 -0.00013900 0.0067720 0.019169"/>
        <joint name="{YOUR_NAME}_joint1" range="-2.7437 2.7437" damping="0.0665" frictionloss="0.2450"/>
        <geom material="white" mesh="link1" class="visual"/>
        <geom mesh="link1_c" class="collision"/>
        <body name="{YOUR_NAME}_link2" quat="1 -1 0 0" gravcomp="1">
          <site name="{YOUR_NAME}_joint2_site" pos="0 0.0 0.0" size=".01 .01 .01" type="ellipsoid" rgba=".8 .2 .1 0"/>
          <inertial mass="0.646926" pos="-0.003141 -0.02872 0.003495"
              fullinertia="0.0079620 2.8110e-2 2.5995e-2 -3.925e-3 1.0254e-2 7.04e-4"/>
          <joint name="{YOUR_NAME}_joint2" range="-1.7837 1.7837" damping="0.1987" frictionloss="0.1523"/>
          <geom material="white" mesh="link2" class="visual"/>
          <geom mesh="link2_c" class="collision"/>
          <body name="{YOUR_NAME}_link3" pos="0 -0.316 0" quat="1 1 0 0" gravcomp="1">
            <site name="{YOUR_NAME}_joint3_site" pos="0 0.0 0.0" size=".01 .01 .01" type="ellipsoid" rgba=".8 .2 .1 0"/>
            <joint name="{YOUR_NAME}_joint3" range="-2.9007 2.9007" damping="0.0399" frictionloss="0.1827"/>
            <inertial mass="3.228604" pos="2.7518e-2 3.9252e-2 -6.6502e-2"
                fullinertia="3.7242e-2 3.6155e-2 1.083e-2 -4.761e-3 -1.1396e-2 -1.2805e-2"/>
            <geom mesh="link3_0" material="white" class="visual"/>
            <geom mesh="link3_1" material="white" class="visual"/>
            <geom mesh="link3_2" material="white" class="visual"/>
            <geom mesh="link3_3" material="black" class="visual"/>
            <geom mesh="link3_c" class="collision"/>
            <body name="{YOUR_NAME}_link4" pos="0.0825 0 0" quat="1 1 0 0" gravcomp="1">
              <site name="{YOUR_NAME}_joint4_site" pos="0 0.0 0.0" size=".01 .01 .01" type="ellipsoid" rgba=".8 .2 .1 0"/>
              <inertial mass="3.587895" pos="-5.317e-2 1.04419e-1 2.7454e-2"
                  fullinertia="2.5853e-2 1.9552e-2 2.8323e-2 7.796e-3 -1.332e-3 8.641e-3"/>
              <joint name="{YOUR_NAME}_joint4" range="-3.0421 -0.1518" damping="0.2257" frictionloss="0.3591"/>
              <geom mesh="link4_0" material="white" class="visual"/>
              <geom mesh="link4_1" material="white" class="visual"/>
              <geom mesh="link4_2" material="black" class="visual"/>
              <geom mesh="link4_3" material="white" class="visual"/>
              <geom mesh="link4_c" class="collision"/>
              <body name="{YOUR_NAME}_link5" pos="-0.0825 0.384 0" quat="1 -1 0 0" gravcomp="1">
                <site name="{YOUR_NAME}_joint5_site" pos="0 0.0 0.0" size=".01 .01 .01" type="ellipsoid" rgba=".8 .2 .1 0"/>          
                <inertial mass="1.225946" pos="-1.1953e-2 4.1065e-2 -3.8437e-2"
                    fullinertia="3.5549e-2 2.9474e-2 8.627e-3 -2.117e-3 -4.037e-3 2.29e-4"/>
                <joint name="{YOUR_NAME}_joint5" range="-2.8065 2.8065" damping="0.1023" frictionloss="0.2669"/>
                <geom mesh="link5_0" material="black" class="visual"/>
                <geom mesh="link5_1" material="white" class="visual"/>
                <geom mesh="link5_2" material="white" class="visual"/>
                <geom mesh="link5_c0" class="collision"/>
                <geom mesh="link5_c1" class="collision"/>
                <geom mesh="link5_c2" class="collision"/>
                <body name="{YOUR_NAME}_link6" quat="1 1 0 0" gravcomp="1">
                  <site name="{YOUR_NAME}_joint6_site" pos="0 0.0 0.0" size=".01 .01 .01" type="ellipsoid" rgba=".8 .2 .1 0"/>
                  <inertial mass="1.666555" pos="6.0149e-2 -1.4117e-2 -1.0517e-2"
                      fullinertia="1.964e-3 4.354e-3 5.433e-3 1.09e-4 -1.158e-3 3.41e-4"/>
                  <joint name="{YOUR_NAME}_joint6" range="0.5445 4.5169" damping="-0.0132" frictionloss="0.1658"/>
                  <geom mesh="link6_0" material="off_white" class="visual"/>
                  <geom mesh="link6_1" material="white" class="visual"/>
                  <geom mesh="link6_2" material="black" class="visual"/>
                  <geom mesh="link6_3" material="white" class="visual"/>
                  <geom mesh="link6_4" material="white" class="visual"/>
                  <geom mesh="link6_5" material="white" class="visual"/>
                  <geom mesh="link6_6" material="white" class="visual"/>
                  <geom mesh="link6_7" material="light_blue" class="visual"/>
                  <geom mesh="link6_8" material="light_blue" class="visual"/>
                  <geom mesh="link6_9" material="black" class="visual"/>
                  <geom mesh="link6_10" material="black" class="visual"/>
                  <geom mesh="link6_11" material="white" class="visual"/>
                  <geom mesh="link6_12" material="green" class="visual"/>
                  <geom mesh="link6_13" material="white" class="visual"/>
                  <geom mesh="link6_14" material="black" class="visual"/>
                  <geom mesh="link6_15" material="black" class="visual"/>
                  <geom mesh="link6_16" material="white" class="visual"/>
                  <geom mesh="link6_c" class="collision"/>
                  <body name="{YOUR_NAME}_link7" pos="0.088 0 0" quat="1 1 0 0" gravcomp="1">
                    <site name="{YOUR_NAME}_joint7_site" pos="0 0.0 0.0" size=".01 .01 .01" type="ellipsoid" rgba=".8 .2 .1 0"/>
                    <inertial mass="7.35522e-01" pos="1.0517e-2 -4.252e-3 6.1597e-2"
                        fullinertia="1.2516e-2 1.0027e-2 4.815e-3 -4.28e-4 -1.196e-3 -7.41e-4"/>
                    <joint name="{YOUR_NAME}_joint7" range="-3.0159 3.0159" damping="0.0638" frictionloss="1.2109"/>
                    <geom mesh="link7_0" material="white" class="visual"/>
                    <geom mesh="link7_1" material="black" class="visual"/>
                    <geom mesh="link7_2" material="black" class="visual"/>
                    <geom mesh="link7_3" material="black" class="visual"/>
                    <geom mesh="link7_4" material="black" class="visual"/>
                    <geom mesh="link7_5" material="black" class="visual"/>
                    <geom mesh="link7_6" material="black" class="visual"/>
                    <geom mesh="link7_7" material="white" class="visual"/>
                    <geom mesh="link7_c" class="collision"/>
                    <body name="{YOUR_NAME}_link8" pos="0 0 0.107" gravcomp="1">
                      <site name="{YOUR_NAME}_flange_site" pos="0 0.0 0.0" size=".01 .01 .01" type="ellipsoid" rgba=".8 .2 .1 0"/>
                      <body name="{YOUR_NAME}_hand" quat="0.9238795 0 0 -0.3826834" gravcomp="1">
                        <inertial mass="0.73" pos="-0.01 0 0.03"
                            diaginertia="0.001 0.0025 0.0017"/>
                        <geom mesh="hand_0" material="off_white" class="visual"/>
                        <geom mesh="hand_1" material="black" class="visual"/>
                        <geom mesh="hand_2" material="black" class="visual"/>
                        <geom mesh="hand_3" material="white" class="visual"/>
                        <geom mesh="hand_4" material="off_white" class="visual"/>
                        <geom mesh="hand_c" class="collision"/>
                        <body pos="0 0 0.1035">
                          <inertial mass="1e-10" pos="0 0 0" diaginertia="1e-10 1e-10 1e-10"/>
                          <site name="{YOUR_NAME}_ee_site" pos="0 0.0 0.0" size=".01 .01 .01" type="ellipsoid" rgba=".8 .2 .1 0"/>
                        </body>  
                        <body name="{YOUR_NAME}_left_finger" pos="0 0 0.0584" gravcomp="1">
                          <inertial mass="0.015" pos="0 0 0"
                              diaginertia="2.375e-6 2.375e-6 7.5e-7"/>
                          <joint name="{YOUR_NAME}_finger_joint1" class="finger"/>
                          <geom mesh="finger_0" material="off_white" class="visual"/>
                          <geom mesh="finger_1" material="black" class="visual"/>
                          <geom mesh="finger_0" class="collision"/>
                          <geom class="fingertip_pad_collision_1"/>
                          <geom class="fingertip_pad_collision_2"/>
                          <geom class="fingertip_pad_collision_3"/>
                          <geom class="fingertip_pad_collision_4"/>
                          <geom class="fingertip_pad_collision_5"/>
                        </body>
                        <body name="{YOUR_NAME}_right_finger" pos="0 0 0.0584" quat="0 0 0 1" gravcomp="1">
                          <inertial mass="0.015" pos="0 0 0"
                              diaginertia="2.375e-6 2.375e-6 7.5e-7"/>
                          <joint name="{YOUR_NAME}_finger_joint2" class="finger"/>
                          <geom mesh="finger_0" material="off_white" class="visual"/>
                          <geom mesh="finger_1" material="black" class="visual"/>
                          <geom mesh="finger_0" class="collision"/>
                          <geom class="fingertip_pad_collision_1"/>
                          <geom class="fingertip_pad_collision_2"/>
                          <geom class="fingertip_pad_collision_3"/>
                          <geom class="fingertip_pad_collision_4"/>
                          <geom class="fingertip_pad_collision_5"/>
                        </body>
                      </body>
                    </body>
                  </body>
                </body>
              </body>
            </body>
          </body>
        </body>
      </body>
    </body>
  </worldbody>

  <contact>
    <exclude body1="{YOUR_NAME}_link7" body2="{YOUR_NAME}_link8"/>
  </contact>

  <tendon>
    <fixed name="split">
      <joint joint="{YOUR_NAME}_finger_joint1" coef="0.5"/>
      <joint joint="{YOUR_NAME}_finger_joint2" coef="0.5"/>
    </fixed>
  </tendon>

  <equality>
    <joint joint1="{YOUR_NAME}_finger_joint1" joint2="{YOUR_NAME}_finger_joint2" solimp="0.95 0.99 0.001" solref="0.005 1"/>
  </equality>

  <actuator>
    <motor name="{YOUR_NAME}_act_trq1" joint="{YOUR_NAME}_joint1" ctrlrange="-87 87" ctrllimited="true"/>
    <motor name="{YOUR_NAME}_act_trq2" joint="{YOUR_NAME}_joint2" ctrlrange="-87 87" ctrllimited="true"/>
    <motor name="{YOUR_NAME}_act_trq3" joint="{YOUR_NAME}_joint3" ctrlrange="-87 87" ctrllimited="true"/>
    <motor name="{YOUR_NAME}_act_trq4" joint="{YOUR_NAME}_joint4" ctrlrange="-87 87" ctrllimited="true"/>
    <motor name="{YOUR_NAME}_act_trq5" joint="{YOUR_NAME}_joint5" ctrlrange="-12 12" ctrllimited="true"/>
    <motor name="{YOUR_NAME}_act_trq6" joint="{YOUR_NAME}_joint6" ctrlrange="-12 12" ctrllimited="true"/>
    <motor name="{YOUR_NAME}_act_trq7" joint="{YOUR_NAME}_joint7" ctrlrange="-12 12" ctrllimited="true"/>

    <position name="{YOUR_NAME}_act_pos1" joint="{YOUR_NAME}_joint1" kp="10" kv="1"/>
    <position name="{YOUR_NAME}_act_pos2" joint="{YOUR_NAME}_joint2" kp="10" kv="1"/>
    <position name="{YOUR_NAME}_act_pos3" joint="{YOUR_NAME}_joint3" kp="10" kv="1"/>
    <position name="{YOUR_NAME}_act_pos4" joint="{YOUR_NAME}_joint4" kp="10" kv="1"/>
    <position name="{YOUR_NAME}_act_pos5" joint="{YOUR_NAME}_joint5" kp="10" kv="1"/>
    <position name="{YOUR_NAME}_act_pos6" joint="{YOUR_NAME}_joint6" kp="10" kv="1"/>
    <position name="{YOUR_NAME}_act_pos7" joint="{YOUR_NAME}_joint7" kp="10" kv="1"/>

    <velocity name="{YOUR_NAME}_act_vel1" joint="{YOUR_NAME}_joint1" kv="1"/>
    <velocity name="{YOUR_NAME}_act_vel2" joint="{YOUR_NAME}_joint2" kv="1"/>
    <velocity name="{YOUR_NAME}_act_vel3" joint="{YOUR_NAME}_joint3" kv="1"/>
    <velocity name="{YOUR_NAME}_act_vel4" joint="{YOUR_NAME}_joint4" kv="1"/>
    <velocity name="{YOUR_NAME}_act_vel5" joint="{YOUR_NAME}_joint5" kv="1"/>
    <velocity name="{YOUR_NAME}_act_vel6" joint="{YOUR_NAME}_joint6" kv="1"/>
    <velocity name="{YOUR_NAME}_act_vel7" joint="{YOUR_NAME}_joint7" kv="1"/>

    <general class="panda" name="{YOUR_NAME}_act_gripper" tendon="split" forcerange="-100 100" ctrlrange="0 255"
        gainprm="0.01568627451 0 0" biasprm="0 -100 -10"/>
  </actuator>


</mujoco>
